Workbook

Sheet Всего
B3: Всего регистрируется абонентов WLL в 04/2026г. на контроллерах RAC ВК ОДТ
B6: Контроллер | C6: кол-во абонентов | D6: Всего по контроллеру
B7: Ука 800 | C7: 505 | D7: 505
B8: Ука 450 | C8: ='Ука 450'!F176 -> 721
B9: Семей 800 | C9: 0 | D9: 0
B10: Семей 450 | C10: 0
B11: Гилат 450 | C11: 0 | D11: 0
B12: Всего | C12: =SUM(C7:C11) -> 1226

Sheet Ука 800
A1: Количество зарегистр. абонентов WLL 800 на секторах БС по РУТам (RAC УКа)
A2: № БС | B2: Наименование БС | C2: № сектора | E2: Всего регистрируется абонентов на базовой станции | F2: Всего регистрируется абонентов по секторам | G2: У-Ка | K2: У-Ка 7723 2 (Новотроицк, Самсоновка) | L2: У-Ка 77232 (Ахмирово, Меновное) | M2: Глубокое 7723 31 | N2: Шемонаиха 7723 32 | S2: Бородулиха 7723 51 | T2: Нов. Шульба 7723 53 | U2: Риддер 7723 36 | X2: Зыряновск 7723 35 | AA2: Серебрянск 7723 37 | AB2: Уланка 7723 38 | AD2: Таврия 7723 34 | AE2: Калбатау 7723 47 | AG2: Большенарым 7723 41 | AI2: Катон-Карагай 7723 42 | AK2: Курчум 7723 39 | AL2: Теректы 7723 43 | AN2: Зайсан 7723 40 | AQ2: Акжар 7723 44 | AS2: Аксуат 7723 46 | AU2: Кокпекты 7723 48 | AW2: Самарское 7723 33 | AZ2: Семей | BJ2: Шульбинск | BK2: Аягоз | BL2: Аягоз 772 37 | BM2: Бескарагaй | BN2: Бескарагай | BO2: Курчатов | BP2: Маканчи | BQ2: Маканчи | BR2: Урджар | BS2: Урджар | BT2: Урджар | BU2: Караул 772 52 | BV2: Павлодар | BW2: Норма на сектор (кол-во абонентов)
G3: 77232216999 | H3: 77232519487 | I3: 77232529999 | J3: 77232544999 | K3: 77232296999 | L3: 77232789999 | M3: 77233155999 | N3: 77233235999 | O3: 77233239999 | P3: 772332772399 | Q3: 77233292999 | R3: 77233298399 | S3: 77235128499 | T3: 77235320999 | U3: 77233623339 | V3: 77233630999 | W3: 77233637599 | X3: 77233550999 | Y3: 77233554999 | Z3: 77233556999 | AA3: 77233726999 | AB3: 77233820999 | AC3: 77233850999 | AD3: 77233420999 | AE3: 77234742999 | AF3: 77234767999 | AG3: 77234120999 | AH3: 77234127999 | AI3: 77234220999 | AJ3: 77234250999 | AK3: 77233924999 | AL3: 77234320999 | AM3: 77234350999 | AN3: 77234020999 | AO3: 77234029999 | AP3: 77234050999 | AQ3: 77234428999 | AR3: 77234450999 | AS3: 77234620999 | AT3: 77234650999 | AU3: 77234820999 | AV3: 77234850999 | AW3: 77233327999 | AX3: 77233350599 | AY3: 77233351999 | AZ3: 7722440999 | BA3: 7722445659 | BB3: 7722450199 | BC3: 7722451374 | BD3: 7722452299 | BE3: 7722453816 | BF3: 7722454099 | BG3: 7722458999 | BH3: 7722638549 | BI3: 7722639899 | BJ3: 7725750399 | BK3: 7723724999 | BL3: 7723765499 | BM3: 7723621299 | BN3: 7723623399 | BO3: 7725127999 | BP3: 7723948999 | BQ3: 7723951099 | BR3: 7723020999 | BS3: 7723029999 | BT3: 7723056549 | BU3: 7725250499 | BV3: 7183841499
G4: 77232210840 | H4: 77232510512 | I4: 77232524160 | J4: 77232544000 | K4: 77232295504 | L4: 77232785000 | M4: 77233150000 | N4: 77233235000 | O4: 77233239000 | P4: 77233272000 | Q4: 77233291100 | R4: 77233297000 | S4: 77235124000 | T4: 77235320000 | U4: 77233620000 | V4: 77233630000 | W4: 77233637000 | X4: 77233550000 | Y4: 77233554000 | Z4: 77233555000 | AA4: 77233726000 | AB4: 77233820000 | AC4: 77233850000 | AD4: 77233420000 | AE4: 77234740000 | AF4: 77234767000 | AG4: 77234120000 | AH4: 77234127000 | AI4: 77234220000 | AJ4: 77234250000 | AK4: 77233922950 | AL4: 77234320000 | AM4: 77234350000 | AN4: 77234020000 | AO4: 77234029000 | AP4: 77234050000 | AQ4: 77234427000 | AR4: 77234450000 | AS4: 77234620000 | AT4: 77234650000 | AU4: 77234820000 | AV4: 77234850000 | AW4: 77233327000 | AX4: 77233350000 | AY4: 77233351000 | AZ4: 7722440000 | BA4: 7722442000 | BB4: 7722450000 | BC4: 7722451000 | BD4: 7722452000 | BE4: 7722453000 | BF4: 7722454000 | BG4: 7722458000 | BH4: 7722630000 | BI4: 7722639400 | BJ4: 7725750000 | BK4: 7723772000 | BL4: 7723765000 | BM4: 7723620000 | BN4: 7723621600 | BO4: 7725127000 | BP4: 7723948000 | BQ4: 7723950000 | BR4: 7723020000 | BS4: 7723029000 | BT4: 7723055000 | BU4: 7725250000 | BV4: 7183841400
A5: 1 | B5: Металлург | C5: 0 | D5: 10 | E5: =SUM(F5:F7) -> 0 | BW5: 780 | BX5: =AO5-BW5 -> -780
C6: 1 | D6: 11 | BW6: 780 | BX6: =AO6-BW6 -> -780
C7: 2 | D7: 12 | BW7: 780 | BX7: =AO7-BW7 -> -780
A8: 2 | B8: Кирзавод | C8: 0 | D8: 20 | E8: =SUM(F8:F10) -> 0 | BW8: 780 | BX8: =AO8-BW8 -> -780
C9: 1 | D9: 21 | BW9: 780 | BX9: =AO9-BW9 -> -780
C10: 2 | D10: 22 | BW10: 780 | BX10: =AO10-BW10 -> -780
A11: 3 | B11: ВК ОДТ | C11: 0 | D11: 30 | E11: =SUM(F11:F13) -> 0 | BW11: 780 | BX11: =AO11-BW11 -> -780
C12: 1 | D12: 31 | BW12: 780 | BX12: =AO12-BW12 -> -780
C13: 2 | D13: 32 | BW13: 780 | BX13: =AO13-BW13 -> -780
A14: 4 | B14: Меновное 800 | C14: 0 | D14: 40 | E14: =SUM(F14:F16) -> 0 | BW14: 780 | BX14: =AO14-BW14 -> -780
C15: 1 | D15: 41 | BW15: 780 | BX15: =AO15-BW15 -> -780
C16: 2 | D16: 42 | BW16: 780 | BX16: =AO16-BW16 -> -780
A17: 5 | B17: ТВ-Центр | C17: 0 | D17: 50 | E17: =SUM(F17:F19) -> 0 | BW17: 780 | BX17: =AO17-BW17 -> -780
C18: 1 | D18: 51 | BW18: 780 | BX18: =AO18-BW18 -> -780
C19: 2 | D19: 52 | BW19: 780 | BX19: =AO19-BW19 -> -780
A20: 6 | B20: АТС-47 | C20: 0 | D20: 60 | E20: =SUM(F20:F22) -> 0 | BW20: 780 | BX20: =AO20-BW20 -> -780
C21: 1 | D21: 61 | BW21: 780 | BX21: =AO21-BW21 -> -780
C22: 2 | D22: 62 | BW22: 780 | BX22: =AO22-BW22 -> -780
A23: 7 | B23: Радужный | C23: 0 | D23: 70 | E23: =SUM(F23:F25) -> 0 | BW23: 780 | BX23: =AO23-BW23 -> -780
C24: 1 | D24: 71 | BW24: 780 | BX24: =AO24-BW24 -> -780
C25: 2 | D25: 72 | BW25: 780 | BX25: =AO25-BW25 -> -780
A26: 25 | B26: Риддер800 | C26: 0 | D26: 250 | E26: =SUM(F26:F28) -> 0 | BW26: 780 | BX26: =AO26-BW26 -> -780
C27: 1 | D27: 251 | BW27: 780 | BX27: =AO27-BW27 -> -780
C28: 2 | D28: 252 | BW28: 780 | BX28: =AO28-BW28 -> -780
A29: Всего Усть-Каменогорск 800 | F29: =SUM(F5:F28) -> 0 | G29: =SUM(G5:G28) -> 0 | H29: =SUM(H5:H28) -> 0 | I29: =SUM(I5:I28) -> 0 | J29: =SUM(J5:J28) -> 0 | K29: =SUM(K5:K28) -> 0 | L29: =SUM(L5:L28) -> 0 | M29: =SUM(M5:M28) -> 0 | ... BV29: =SUM(BV5:BV28) -> 0

Sheet Ука 450
B1: Количество зарегистрированных абонентов WLL 450 на секторах БС по РУТам (RAC U-Ka)
A2: № БС | B2: Наименование БС | C2: № сектора | E2: Всего регистрируется по базовой станции | F2: Всего регистрируется абонентов по секторам | G2: У-Ка | K2: У-Ка 7723 2 (Новотроицк, Самсоновка) | L2: У-Ка 77232 (Ахмирово, Меновное) | M2: Глубокое 7723 31 | N2: Шемонаиха 7723 32 | S2: Бородулиха 7723 51 | T2: Нов. Шульба 7723 53 | U2: Риддер 7723 36 | X2: Зыряновск 7723 35 | AA2: Серебрянск 7723 37 | AB2: Уланка 7723 38 | AD2: Таврия 7723 34 | AE2: Калбатау 7723 47 | AG2: Большенарым 7723 41 | AI2: Катон-Карагай 7723 42 | AK2: Курчум 7723 39 | AL2: Теректы 7723 43 | AN2: Зайсан 7723 40 | AQ2: Акжар 7723 44 | AS2: Аксуат 7723 46 | AU2: Кокпекты 7723 48 | AW2: Самарское 7723 33 | AZ2: Семей | BJ2: Шульбинск | BK2: Бескарагaй | BL2: Бескарагай | BM2: Курчатов | BN2: Аягоз 772 37 | BP2: Маканчи | BQ2: Маканчи | BR2: Урджар | BS2: Урджар | BT2: Урджар | BU2: Караул 772 52 | BV2: Павлодар | BW2: Норма на сектор (кол-во абонентов)
G3: 77232216999 | H3: 77232519487 | I3: 77232529999 | J3: 77232544999 | K3: 77232296999 | L3: 77232789999 | M3: 77233155999 | N3: 77233235999 | O3: 77233239999 | P3: 77233272999 | Q3: 77233292999 | R3: 77233298399 | S3: 77235128499 | T3: 77235320999 | U3: 77233623339 | V3: 77233630999 | W3: 77233637599 | X3: 77233550999 | Y3: 77233554999 | Z3: 77233556999 | AA3: 77233726999 | AB3: 77233820999 | AC3: 77233850999 | AD3: 77233420999 | AE3: 77234742999 | AF3: 77234767999 | AG3: 77234120999 | AH3: 77234127999 | AI3: 77234220999 | AJ3: 77234250999 | AK3: 77233924999 | AL3: 77234320999 | AM3: 77234350999 | AN3: 77234020999 | AO3: 77234029999 | AP3: 77234050999 | AQ3: 77234428999 | AR3: 77234450999 | AS3: 77234620999 | AT3: 77234650999 | AU3: 77234820999 | AV3: 77234850999 | AW3: 77233327999 | AX3: 77233350599 | AY3: 77233351999 | AZ3: 7722440999 | BA3: 7722445659 | BB3: 7722450199 | BC3: 7722451374 | BD3: 7722452299 | BE3: 7722453816 | BF3: 7722454099 | BG3: 7722458999 | BH3: 7722638549 | BI3: 7722639899 | BJ3: 7725750399 | BK3: 7723621299 | BL3: 7723623399 | BM3: 7725127999 | BN3: 7723724999 | BO3: 7723765499 | BP3: 7723948999 | BQ3: 7723951099 | BR3: 7723020999 | BS3: 7723029999 | BT3: 7723056549 | BU3: 7725250499 | BV3: 7183841499
G4: 77232210840 | H4: 77232510512 | I4: 77232524160 | J4: 77232544000 | K4: 77232295504 | L4: 77232785000 | M4: 77233150000 | N4: 77233235000 | O4: 77233239000 | P4: 77233272000 | Q4: 77233291100 | R4: 77233297000 | S4: 77235124000 | T4: 77235320000 | U4: 77233620000 | V4: 77233630000 | W4: 77233637000 | X4: 77233550000 | Y4: 77233554000 | Z4: 77233555000 | AA4: 77233726000 | AB4: 77233820000 | AC4: 77233850000 | AD4: 77233420000 | AE4: 77234740000 | AF4: 77234767000 | AG4: 77234120000 | AH4: 77234127000 | AI4: 77234220000 | AJ4: 77234250000 | AK4: 77233922950 | AL4: 77234320000 | AM4: 77234350000 | AN4: 77234020000 | AO4: 77234029000 | AP4: 77234050000 | AQ4: 77234427000 | AR4: 77234450000 | AS4: 77234620000 | AT4: 77234650000 | AU4: 77234820000 | AV4: 77234850000 | AW4: 77233327000 | AX4: 77233350000 | AY4: 77233351000 | AZ4: 7722440000 | BA4: 7722442000 | BB4: 7722450000 | BC4: 7722451000 | BD4: 7722452000 | BE4: 7722453000 | BF4: 7722454000 | BG4: 7722458000 | BH4: 7722630000 | BI4: 7722639400 | BJ4: 7725750000 | BK4: 7723620000 | BL4: 7723621600 | BM4: 7725127000 | BN4: 7723772000 | BO4: 7723765000 | BP4: 7723948000 | BQ4: 7723950000 | BR4: 7723020000 | BS4: 7723029000 | BT4: 7723055000 | BU4: 7725250000 | BV4: 7183841400
A5: 8 | B5: Катон-Карагай | C5: 0 | D5: 80 | E5: =SUM(F5:F7) -> 0 | F5: =COUNTIFS(Данные!$B$2:$B$722,8,Данные!$C$2:$C$722,0) -> 0 | G5: =COUNTIFS(Данные!$B$2:$B$722,8,Данные!$C$2:$C$722,0,Данные!$A$2:$A$722,">="&77232210840,Данные!$A$2:$A$722,"<="&77232216999) -> 0 | H5: =COUNTIFS(Данные!$B$2:$B$722,8,Данные!$C$2:$C$722,0,Данные!$A$2:$A$722,">="&77232510512,Данные!$A$2:$A$722,"<="&77232519487) -> 0 | I5: =COUNTIFS(Данные!$B$2:$B$722,8,Данные!$C$2:$C$722,0,Данные!$A$2:$A$722,">="&77232524160,Данные!$A$2:$A$722,"<="&77232529999) -> 0 | J5: =COUNTIFS(Данные!$B$2:$B$722,8,Данные!$C$2:$C$722,0,Данные!$A$2:$A$722,">="&77232544000,Данные!$A$2:$A$722,"<="&77232544999) -> 0 | K5: =COUNTIFS(Данные!$B$2:$B$722,8,Данные!$C$2:$C$722,0,Данные!$A$2:$A$722,">="&77232295504,Данные!$A$2:$A$722,"<="&77232296999) -> 0 | L5: =COUNTIFS(Данные!$B$2:$B$722,8,Данные!$C$2:$C$722,0,Данные!$A$2:$A$722,">="&77232785000,Данные!$A$2:$A$722,"<="&77232789999) -> 0 | M5: =COUNTIFS(Данные!$B$2:$B$722,8,Данные!$C$2:$C$722,0,Данные!$A$2:$A$722,">="&77233150000,Данные!$A$2:$A$722,"<="&77233155999) -> 0 | N5: =COUNTIFS(Данные!$B$2:$B$722,8,Данные!$C$2:$C$722,0,Данные!$A$2:$A$722,">="&77233235000,Данные!$A$2:$A$722,"<="&77233235999) -> 0 | O5: =COUNTIFS(Данные!$B$2:$B$722,8,Данные!$C$2:$C$722,0,Данные!$A$2:$A$722,">="&77233239000,Данные!$A$2:$A$722,"<="&77233239999) -> 0 | P5: =COUNTIFS(Данные!$B$2:$B$722,8,Данные!$C$2:$C$722,0,Данные!$A$2:$A$722,">="&77233272000,Данные!$A$2:$A$722,"<="&77233272999) -> 0 | Q5: =COUNTIFS(Данные!$B$2:$B$722,8,Данные!$C$2:$C$722,0,Данные!$A$2:$A$722,">="&77233291100,Данные!$A$2:$A$722,"<="&77233292999) -> 0 | R5: =COUNTIFS(Данные!$B$2:$B$722,8,Данные!$C$2:$C$722,0,Данные!$A$2:$A$722,">="&77233297000,Данные!$A$2:$A$722,"<="&77233298399) -> 0 | S5: =COUNTIFS(Данные!$B$2:$B$722,8,Данные!$C$2:$C$722,0,Данные!$A$2:$A$722,">="&77235124000,Данные!$A$2:$A$722,"<="&77235128499) -> 0 | T5: =COUNTIFS(Данные!$B$2:$B$722,8,Данные!$C$2:$C$722,0,Данные!$A$2:$A$722,">="&77235320000,Данные!$A$2:$A$722,"<="&77235320999) -> 0 | U5: =COUNTIFS(Данные!$B$2:$B$722,8,Данные!$C$2:$C$722,0,Данные!$A$2:$A$722,">="&77233620000,Данные!$A$2:$A$722,"<="&77233623339) -> 0 | V5: =COUNTIFS(Данные!$B$2:$B$722,8,Данные!$C$2:$C$722,0,Данные!$A$2:$A$722,">="&77233630000,Данные!$A$2:$A$722,"<="&77233630999) -> 0 | W5: =COUNTIFS(Данные!$B$2:$B$722,8,Данные!$C$2:$C$722,0,Данные!$A$2:$A$722,">="&77233637000,Данные!$A$2:$A$722,"<="&77233637599) -> 0 | X5: =COUNTIFS(Данные!$B$2:$B$722,8,Данные!$C$2:$C$722,0,Данные!$A$2:$A$722,">="&77233550000,Данные!$A$2:$A$722,"<="&77233550999) -> 0 | Y5: =COUNTIFS(Данные!$B$2:$B$722,8,Данные!$C$2:$C$722,0,Данные!$A$2:$A$722,">="&77233554000,Данные!$A$2:$A$722,"<="&77233554999) -> 0 | Z5: =COUNTIFS(Данные!$B$2:$B$722,8,Данные!$C$2:$C$722,0,Данные!$A$2:$A$722,">="&77233555000,Данные!$A$2:$A$722,"<="&77233556999) -> 0 | AA5: =COUNTIFS(Данные!$B$2:$B$722,8,Данные!$C$2:$C$722,0,Данные!$A$2:$A$722,">="&77233726000,Данные!$A$2:$A$722,"<="&77233726999) -> 0 | AB5: =COUNTIFS(Данные!$B$2:$B$722,8,Данные!$C$2:$C$722,0,Данные!$A$2:$A$722,">="&77233820000,Данные!$A$2:$A$722,"<="&77233820999) -> 0 | AC5: =COUNTIFS(Данные!$B$2:$B$722,8,Данные!$C$2:$C$722,0,Данные!$A$2:$A$722,">="&77233850000,Данные!$A$2:$A$722,"<="&77233850999) -> 0 | AD5: =COUNTIFS(Данные!$B$2:$B$722,8,Данные!$C$2:$C$722,0,Данные!$A$2:$A$722,">="&77233420000,Данные!$A$2:$A$722,"<="&77233420999) -> 0 | AE5: =COUNTIFS(Данные!$B$2:$B$722,8,Данные!$C$2:$C$722,0,Данные!$A$2:$A$722,">="&77234740000,Данные!$A$2:$A$722,"<="&77234742999) -> 0 | AF5: =COUNTIFS(Данные!$B$2:$B$722,8,Данные!$C$2:$C$722,0,Данные!$A$2:$A$722,">="&77234767000,Данные!$A$2:$A$722,"<="&77234767999) -> 0 | AG5: =COUNTIFS(Данные!$B$2:$B$722,8,Данные!$C$2:$C$722,0,Данные!$A$2:$A$722,">="&77234120000,Данные!$A$2:$A$722,"<="&77234120999) -> 0 | AH5: =COUNTIFS(Данные!$B$2:$B$722,8,Данные!$C$2:$C$722,0,Данные!$A$2:$A$722,">="&77234127000,Данные!$A$2:$A$722,"<="&77234127999) -> 0 | AI5: =COUNTIFS(Данные!$B$2:$B$722,8,Данные!$C$2:$C$722,0,Данные!$A$2:$A$722,">="&77234220000,Данные!$A$2:$A$722,"<="&77234220999) -> 0 | AJ5: =COUNTIFS(Данные!$B$2:$B$722,8,Данные!$C$2:$C$722,0,Данные!$A$2:$A$722,">="&77234250000,Данные!$A$2:$A$722,"<="&77234250999) -> 0 | AK5: =COUNTIFS(Данные!$B$2:$B$722,8,Данные!$C$2:$C$722,0,Данные!$A$2:$A$722,">="&77233922950,Данные!$A$2:$A$722,"<="&77233924999) -> 0 | AL5: =COUNTIFS(Данные!$B$2:$B$722,8,Данные!$C$2:$C$722,0,Данные!$A$2:$A$722,">="&77234320000,Данные!$A$2:$A$722,"<="&77234320999) -> 0 | AM5: =COUNTIFS(Данные!$B$2:$B$722,8,Данные!$C$2:$C$722,0,Данные!$A$2:$A$722,">="&77234350000,Данные!$A$2:$A$722,"<="&77234350999) -> 0 | AN5: =COUNTIFS(Данные!$B$2:$B$722,8,Данные!$C$2:$C$722,0,Данные!$A$2:$A$722,">="&77234020000,Данные!$A$2:$A$722,"<="&77234020999) -> 0 | AO5: =COUNTIFS(Данные!$B$2:$B$722,8,Данные!$C$2:$C$722,0,Данные!$A$2:$A$722,">="&77234029000,Данные!$A$2:$A$722,"<="&77234029999) -> 0 | AP5: =COUNTIFS(Данные!$B$2:$B$722,8,Данные!$C$2:$C$722,0,Данные!$A$2:$A$722,">="&77234050000,Данные!$A$2:$A$722,"<="&77234050999) -> 0 | AQ5: =COUNTIFS(Данные!$B$2:$B$722,8,Данные!$C$2:$C$722,0,Данные!$A$2:$A$722,">="&77234427000,Данные!$A$2:$A$722,"<="&77234428999) -> 0 | AR5: =COUNTIFS(Данные!$B$2:$B$722,8,Данные!$C$2:$C$722,0,Данные!$A$2:$A$722,">="&77234450000,Данные!$A$2:$A$722,"<="&77234450999) -> 0 | AS5: =COUNTIFS(Данные!$B$2:$B$722,8,Данные!$C$2:$C$722,0,Данные!$A$2:$A$722,">="&77234620000,Данные!$A$2:$A$722,"<="&77234620999) -> 0 | AT5: =COUNTIFS(Данные!$B$2:$B$722,8,Данные!$C$2:$C$722,0,Данные!$A$2:$A$722,">="&77234650000,Данные!$A$2:$A$722,"<="&77234650999) -> 0 | AU5: =COUNTIFS(Данные!$B$2:$B$722,8,Данные!$C$2:$C$722,0,Данные!$A$2:$A$722,">="&77234820000,Данные!$A$2:$A$722,"<="&77234820999) -> 0 | AV5: =COUNTIFS(Данные!$B$2:$B$722,8,Данные!$C$2:$C$722,0,Данные!$A$2:$A$722,">="&77234850000,Данные!$A$2:$A$722,"<="&77234850999) -> 0 | AW5: =COUNTIFS(Данные!$B$2:$B$722,8,Данные!$C$2:$C$722,0,Данные!$A$2:$A$722,">="&77233327000,Данные!$A$2:$A$722,"<="&77233327999) -> 0 | AX5: =COUNTIFS(Данные!$B$2:$B$722,8,Данные!$C$2:$C$722,0,Данные!$A$2:$A$722,">="&77233350000,Данные!$A$2:$A$722,"<="&77233350599) -> 0 | AY5: =COUNTIFS(Данные!$B$2:$B$722,8,Данные!$C$2:$C$722,0,Данные!$A$2:$A$722,">="&77233351000,Данные!$A$2:$A$722,"<="&77233351999) -> 0 | AZ5: =COUNTIFS(Данные!$B$2:$B$722,8,Данные!$C$2:$C$722,0,Данные!$A$2:$A$722,">="&7722440000,Данные!$A$2:$A$722,"<="&7722440999) -> 0 | BA5: =COUNTIFS(Данные!$B$2:$B$722,8,Данные!$C$2:$C$722,0,Данные!$A$2:$A$722,">="&7722442000,Данные!$A$2:$A$722,"<="&7722445659) -> 0 | BB5: =COUNTIFS(Данные!$B$2:$B$722,8,Данные!$C$2:$C$722,0,Данные!$A$2:$A$722,">="&7722450000,Данные!$A$2:$A$722,"<="&7722450199) -> 0 | BC5: =COUNTIFS(Данные!$B$2:$B$722,8,Данные!$C$2:$C$722,0,Данные!$A$2:$A$722,">="&7722451000,Данные!$A$2:$A$722,"<="&7722451374) -> 0 | BD5: =COUNTIFS(Данные!$B$2:$B$722,8,Данные!$C$2:$C$722,0,Данные!$A$2:$A$722,">="&7722452000,Данные!$A$2:$A$722,"<="&7722452299) -> 0 | BE5: =COUNTIFS(Данные!$B$2:$B$722,8,Данные!$C$2:$C$722,0,Данные!$A$2:$A$722,">="&7722453000,Данные!$A$2:$A$722,"<="&7722453816) -> 0 | BF5: =COUNTIFS(Данные!$B$2:$B$722,8,Данные!$C$2:$C$722,0,Данные!$A$2:$A$722,">="&7722454000,Данные!$A$2:$A$722,"<="&7722454099) -> 0 | BG5: =COUNTIFS(Данные!$B$2:$B$722,8,Данные!$C$2:$C$722,0,Данные!$A$2:$A$722,">="&7722458000,Данные!$A$2:$A$722,"<="&7722458999) -> 0 | BH5: =COUNTIFS(Данные!$B$2:$B$722,8,Данные!$C$2:$C$722,0,Данные!$A$2:$A$722,">="&7722630000,Данные!$A$2:$A$722,"<="&7722638549) -> 0 | BI5: =COUNTIFS(Данные!$B$2:$B$722,8,Данные!$C$2:$C$722,0,Данные!$A$2:$A$722,">="&7722639400,Данные!$A$2:$A$722,"<="&7722639899) -> 0 | BJ5: =COUNTIFS(Данные!$B$2:$B$722,8,Данные!$C$2:$C$722,0,Данные!$A$2:$A$722,">="&7725750000,Данные!$A$2:$A$722,"<="&7725750399) -> 0 | BK5: =COUNTIFS(Данные!$B$2:$B$722,8,Данные!$C$2:$C$722,0,Данные!$A$2:$A$722,">="&7723620000,Данные!$A$2:$A$722,"<="&7723621299) -> 0 | BL5: =COUNTIFS(Данные!$B$2:$B$722,8,Данные!$C$2:$C$722,0,Данные!$A$2:$A$722,">="&7723621600,Данные!$A$2:$A$722,"<="&7723623399) -> 0 | BM5: =COUNTIFS(Данные!$B$2:$B$722,8,Данные!$C$2:$C$722,0,Данные!$A$2:$A$722,">="&7725127000,Данные!$A$2:$A$722,"<="&7725127999) -> 0 | BN5: =COUNTIFS(Данные!$B$2:$B$722,8,Данные!$C$2:$C$722,0,Данные!$A$2:$A$722,">="&7723772000,Данные!$A$2:$A$722,"<="&7723724999) -> 0 | BO5: =COUNTIFS(Данные!$B$2:$B$722,8,Данные!$C$2:$C$722,0,Данные!$A$2:$A$722,">="&7723765000,Данные!$A$2:$A$722,"<="&7723765499) -> 0 | BP5: =COUNTIFS(Данные!$B$2:$B$722,8,Данные!$C$2:$C$722,0,Данные!$A$2:$A$722,">="&7723948000,Данные!$A$2:$A$722,"<="&7723948999) -> 0 | BQ5: =COUNTIFS(Данные!$B$2:$B$722,8,Данные!$C$2:$C$722,0,Данные!$A$2:$A$722,">="&7723950000,Данные!$A$2:$A$722,"<="&7723951099) -> 0 | BR5: =COUNTIFS(Данные!$B$2:$B$722,8,Данные!$C$2:$C$722,0,Данные!$A$2:$A$722,">="&7723020000,Данные!$A$2:$A$722,"<="&7723020999) -> 0 | BS5: =COUNTIFS(Данные!$B$2:$B$722,8,Данные!$C$2:$C$722,0,Данные!$A$2:$A$722,">="&7723029000,Данные!$A$2:$A$722,"<="&7723029999) -> 0 | BT5: =COUNTIFS(Данные!$B$2:$B$722,8,Данные!$C$2:$C$722,0,Данные!$A$2:$A$722,">="&7723055000,Данные!$A$2:$A$722,"<="&7723056549) -> 0 | BU5: =COUNTIFS(Данные!$B$2:$B$722,8,Данные!$C$2:$C$722,0,Данные!$A$2:$A$722,">="&7725250000,Данные!$A$2:$A$722,"<="&7725250499) -> 0 | BV5: =COUNTIFS(Данные!$B$2:$B$722,8,Данные!$C$2:$C$722,0,Данные!$A$2:$A$722,">="&7183841400,Данные!$A$2:$A$722,"<="&7183841499) -> 0 | BW5: 300 | BX5: =F5-BW5 -> -300
C6: 1 | D6: 81 | F6: =COUNTIFS(Данные!$B$2:$B$722,8,Данные!$C$2:$C$722,1) -> 0 | G6: =COUNTIFS(Данные!$B$2:$B$722,8,Данные!$C$2:$C$722,1,Данные!$A$2:$A$722,">="&77232210840,Данные!$A$2:$A$722,"<="&77232216999) -> 0 | H6: =COUNTIFS(Данные!$B$2:$B$722,8,Данные!$C$2:$C$722,1,Данные!$A$2:$A$722,">="&77232510512,Данные!$A$2:$A$722,"<="&77232519487) -> 0 | I6: =COUNTIFS(Данные!$B$2:$B$722,8,Данные!$C$2:$C$722,1,Данные!$A$2:$A$722,">="&77232524160,Данные!$A$2:$A$722,"<="&77232529999) -> 0 | J6: =COUNTIFS(Данные!$B$2:$B$722,8,Данные!$C$2:$C$722,1,Данные!$A$2:$A$722,">="&77232544000,Данные!$A$2:$A$722,"<="&77232544999) -> 0 | K6: =COUNTIFS(Данные!$B$2:$B$722,8,Данные!$C$2:$C$722,1,Данные!$A$2:$A$722,">="&77232295504,Данные!$A$2:$A$722,"<="&77232296999) -> 0 | L6: =COUNTIFS(Данные!$B$2:$B$722,8,Данные!$C$2:$C$722,1,Данные!$A$2:$A$722,">="&77232785000,Данные!$A$2:$A$722,"<="&77232789999) -> 0 | M6: =COUNTIFS(Данные!$B$2:$B$722,8,Данные!$C$2:$C$722,1,Данные!$A$2:$A$722,">="&77233150000,Данные!$A$2:$A$722,"<="&77233155999) -> 0 | N6: =COUNTIFS(Данные!$B$2:$B$722,8,Данные!$C$2:$C$722,1,Данные!$A$2:$A$722,">="&77233235000,Данные!$A$2:$A$722,"<="&77233235999) -> 0 | O6: =COUNTIFS(Данные!$B$2:$B$722,8,Данные!$C$2:$C$722,1,Данные!$A$2:$A$722,">="&77233239000,Данные!$A$2:$A$722,"<="&77233239999) -> 0 | P6: =COUNTIFS(Данные!$B$2:$B$722,8,Данные!$C$2:$C$722,1,Данные!$A$2:$A$722,">="&77233272000,Данные!$A$2:$A$722,"<="&77233272999) -> 0 | Q6: =COUNTIFS(Данные!$B$2:$B$722,8,Данные!$C$2:$C$722,1,Данные!$A$2:$A$722,">="&77233291100,Данные!$A$2:$A$722,"<="&77233292999) -> 0 | R6: =COUNTIFS(Данные!$B$2:$B$722,8,Данные!$C$2:$C$722,1,Данные!$A$2:$A$722,">="&77233297000,Данные!$A$2:$A$722,"<="&77233298399) -> 0 | S6: =COUNTIFS(Данные!$B$2:$B$722,8,Данные!$C$2:$C$722,1,Данные!$A$2:$A$722,">="&77235124000,Данные!$A$2:$A$722,"<="&77235128499) -> 0 | T6: =COUNTIFS(Данные!$B$2:$B$722,8,Данные!$C$2:$C$722,1,Данные!$A$2:$A$722,">="&77235320000,Данные!$A$2:$A$722,"<="&77235320999) -> 0 | U6: =COUNTIFS(Данные!$B$2:$B$722,8,Данные!$C$2:$C$722,1,Данные!$A$2:$A$722,">="&77233620000,Данные!$A$2:$A$722,"<="&77233623339) -> 0 | V6: =COUNTIFS(Данные!$B$2:$B$722,8,Данные!$C$2:$C$722,1,Данные!$A$2:$A$722,">="&77233630000,Данные!$A$2:$A$722,"<="&77233630999) -> 0 | W6: =COUNTIFS(Данные!$B$2:$B$722,8,Данные!$C$2:$C$722,1,Данные!$A$2:$A$722,">="&77233637000,Данные!$A$2:$A$722,"<="&77233637599) -> 0 | X6: =COUNTIFS(Данные!$B$2:$B$722,8,Данные!$C$2:$C$722,1,Данные!$A$2:$A$722,">="&77233550000,Данные!$A$2:$A$722,"<="&77233550999) -> 0 | Y6: =COUNTIFS(Данные!$B$2:$B$722,8,Данные!$C$2:$C$722,1,Данные!$A$2:$A$722,">="&77233554000,Данные!$A$2:$A$722,"<="&77233554999) -> 0 | Z6: =COUNTIFS(Данные!$B$2:$B$722,8,Данные!$C$2:$C$722,1,Данные!$A$2:$A$722,">="&77233555000,Данные!$A$2:$A$722,"<="&77233556999) -> 0 | AA6: =COUNTIFS(Данные!$B$2:$B$722,8,Данные!$C$2:$C$722,1,Данные!$A$2:$A$722,">="&77233726000,Данные!$A$2:$A$722,"<="&77233726999) -> 0 | AB6: =COUNTIFS(Данные!$B$2:$B$722,8,Данные!$C$2:$C$722,1,Данные!$A$2:$A$722,">="&77233820000,Данные!$A$2:$A$722,"<="&77233820999) -> 0 | AC6: =COUNTIFS(Данные!$B$2:$B$722,8,Данные!$C$2:$C$722,1,Данные!$A$2:$A$722,">="&77233850000,Данные!$A$2:$A$722,"<="&77233850999) -> 0 | AD6: =COUNTIFS(Данные!$B$2:$B$722,8,Данные!$C$2:$C$722,1,Данные!$A$2:$A$722,">="&77233420000,Данные!$A$2:$A$722,"<="&77233420999) -> 0 | AE6: =COUNTIFS(Данные!$B$2:$B$722,8,Данные!$C$2:$C$722,1,Данные!$A$2:$A$722,">="&77234740000,Данные!$A$2:$A$722,"<="&77234742999) -> 0 | AF6: =COUNTIFS(Данные!$B$2:$B$722,8,Данные!$C$2:$C$722,1,Данные!$A$2:$A$722,">="&77234767000,Данные!$A$2:$A$722,"<="&77234767999) -> 0 | AG6: =COUNTIFS(Данные!$B$2:$B$722,8,Данные!$C$2:$C$722,1,Данные!$A$2:$A$722,">="&77234120000,Данные!$A$2:$A$722,"<="&77234120999) -> 0 | AH6: =COUNTIFS(Данные!$B$2:$B$722,8,Данные!$C$2:$C$722,1,Данные!$A$2:$A$722,">="&77234127000,Данные!$A$2:$A$722,"<="&77234127999) -> 0 | AI6: =COUNTIFS(Данные!$B$2:$B$722,8,Данные!$C$2:$C$722,1,Данные!$A$2:$A$722,">="&77234220000,Данные!$A$2:$A$722,"<="&77234220999) -> 0 | AJ6: =COUNTIFS(Данные!$B$2:$B$722,8,Данные!$C$2:$C$722,1,Данные!$A$2:$A$722,">="&77234250000,Данные!$A$2:$A$722,"<="&77234250999) -> 0 | AK6: =COUNTIFS(Данные!$B$2:$B$722,8,Данные!$C$2:$C$722,1,Данные!$A$2:$A$722,">="&77233922950,Данные!$A$2:$A$722,"<="&77233924999) -> 0 | AL6: =COUNTIFS(Данные!$B$2:$B$722,8,Данные!$C$2:$C$722,1,Данные!$A$2:$A$722,">="&77234320000,Данные!$A$2:$A$722,"<="&77234320999) -> 0 | AM6: =COUNTIFS(Данные!$B$2:$B$722,8,Данные!$C$2:$C$722,1,Данные!$A$2:$A$722,">="&77234350000,Данные!$A$2:$A$722,"<="&77234350999) -> 0 | AN6: =COUNTIFS(Данные!$B$2:$B$722,8,Данные!$C$2:$C$722,1,Данные!$A$2:$A$722,">="&77234020000,Данные!$A$2:$A$722,"<="&77234020999) -> 0 | AO6: =COUNTIFS(Данные!$B$2:$B$722,8,Данные!$C$2:$C$722,1,Данные!$A$2:$A$722,">="&77234029000,Данные!$A$2:$A$722,"<="&77234029999) -> 0 | AP6: =COUNTIFS(Данные!$B$2:$B$722,8,Данные!$C$2:$C$722,1,Данные!$A$2:$A$722,">="&77234050000,Данные!$A$2:$A$722,"<="&77234050999) -> 0 | AQ6: =COUNTIFS(Данные!$B$2:$B$722,8,Данные!$C$2:$C$722,1,Данные!$A$2:$A$722,">="&77234427000,Данные!$A$2:$A$722,"<="&77234428999) -> 0 | AR6: =COUNTIFS(Данные!$B$2:$B$722,8,Данные!$C$2:$C$722,1,Данные!$A$2:$A$722,">="&77234450000,Данные!$A$2:$A$722,"<="&77234450999) -> 0 | AS6: =COUNTIFS(Данные!$B$2:$B$722,8,Данные!$C$2:$C$722,1,Данные!$A$2:$A$722,">="&77234620000,Данные!$A$2:$A$722,"<="&77234620999) -> 0 | AT6: =COUNTIFS(Данные!$B$2:$B$722,8,Данные!$C$2:$C$722,1,Данные!$A$2:$A$722,">="&77234650000,Данные!$A$2:$A$722,"<="&77234650999) -> 0 | AU6: =COUNTIFS(Данные!$B$2:$B$722,8,Данные!$C$2:$C$722,1,Данные!$A$2:$A$722,">="&77234820000,Данные!$A$2:$A$722,"<="&77234820999) -> 0 | AV6: =COUNTIFS(Данные!$B$2:$B$722,8,Данные!$C$2:$C$722,1,Данные!$A$2:$A$722,">="&77234850000,Данные!$A$2:$A$722,"<="&77234850999) -> 0 | AW6: =COUNTIFS(Данные!$B$2:$B$722,8,Данные!$C$2:$C$722,1,Данные!$A$2:$A$722,">="&77233327000,Данные!$A$2:$A$722,"<="&77233327999) -> 0 | AX6: =COUNTIFS(Данные!$B$2:$B$722,8,Данные!$C$2:$C$722,1,Данные!$A$2:$A$722,">="&77233350000,Данные!$A$2:$A$722,"<="&77233350599) -> 0 | AY6: =COUNTIFS(Данные!$B$2:$B$722,8,Данные!$C$2:$C$722,1,Данные!$A$2:$A$722,">="&77233351000,Данные!$A$2:$A$722,"<="&77233351999) -> 0 | AZ6: =COUNTIFS(Данные!$B$2:$B$722,8,Данные!$C$2:$C$722,1,Данные!$A$2:$A$722,">="&7722440000,Данные!$A$2:$A$722,"<="&7722440999) -> 0 | BA6: =COUNTIFS(Данные!$B$2:$B$722,8,Данные!$C$2:$C$722,1,Данные!$A$2:$A$722,">="&7722442000,Данные!$A$2:$A$722,"<="&7722445659) -> 0 | BB6: =COUNTIFS(Данные!$B$2:$B$722,8,Данные!$C$2:$C$722,1,Данные!$A$2:$A$722,">="&7722450000,Данные!$A$2:$A$722,"<="&7722450199) -> 0 | BC6: =COUNTIFS(Данные!$B$2:$B$722,8,Данные!$C$2:$C$722,1,Данные!$A$2:$A$722,">="&7722451000,Данные!$A$2:$A$722,"<="&7722451374) -> 0 | BD6: =COUNTIFS(Данные!$B$2:$B$722,8,Данные!$C$2:$C$722,1,Данные!$A$2:$A$722,">="&7722452000,Данные!$A$2:$A$722,"<="&7722452299) -> 0 | BE6: =COUNTIFS(Данные!$B$2:$B$722,8,Данные!$C$2:$C$722,1,Данные!$A$2:$A$722,">="&7722453000,Данные!$A$2:$A$722,"<="&7722453816) -> 0 | BF6: =COUNTIFS(Данные!$B$2:$B$722,8,Данные!$C$2:$C$722,1,Данные!$A$2:$A$722,">="&7722454000,Данные!$A$2:$A$722,"<="&7722454099) -> 0 | BG6: =COUNTIFS(Данные!$B$2:$B$722,8,Данные!$C$2:$C$722,1,Данные!$A$2:$A$722,">="&7722458000,Данные!$A$2:$A$722,"<="&7722458999) -> 0 | BH6: =COUNTIFS(Данные!$B$2:$B$722,8,Данные!$C$2:$C$722,1,Данные!$A$2:$A$722,">="&7722630000,Данные!$A$2:$A$722,"<="&7722638549) -> 0 | BI6: =COUNTIFS(Данные!$B$2:$B$722,8,Данные!$C$2:$C$722,1,Данные!$A$2:$A$722,">="&7722639400,Данные!$A$2:$A$722,"<="&7722639899) -> 0 | BJ6: =COUNTIFS(Данные!$B$2:$B$722,8,Данные!$C$2:$C$722,1,Данные!$A$2:$A$722,">="&7725750000,Данные!$A$2:$A$722,"<="&7725750399) -> 0 | BK6: =COUNTIFS(Данные!$B$2:$B$722,8,Данные!$C$2:$C$722,1,Данные!$A$2:$A$722,">="&7723620000,Данные!$A$2:$A$722,"<="&7723621299) -> 0 | BL6: =COUNTIFS(Данные!$B$2:$B$722,8,Данные!$C$2:$C$722,1,Данные!$A$2:$A$722,">="&7723621600,Данные!$A$2:$A$722,"<="&7723623399) -> 0 | BM6: =COUNTIFS(Данные!$B$2:$B$722,8,Данные!$C$2:$C$722,1,Данные!$A$2:$A$722,">="&7725127000,Данные!$A$2:$A$722,"<="&7725127999) -> 0 | BN6: =COUNTIFS(Данные!$B$2:$B$722,8,Данные!$C$2:$C$722,1,Данные!$A$2:$A$722,">="&7723772000,Данные!$A$2:$A$722,"<="&7723724999) -> 0 | BO6: =COUNTIFS(Данные!$B$2:$B$722,8,Данные!$C$2:$C$722,1,Данные!$A$2:$A$722,">="&7723765000,Данные!$A$2:$A$722,"<="&7723765499) -> 0 | BP6: =COUNTIFS(Данные!$B$2:$B$722,8,Данные!$C$2:$C$722,1,Данные!$A$2:$A$722,">="&7723948000,Данные!$A$2:$A$722,"<="&7723948999) -> 0 | BQ6: =COUNTIFS(Данные!$B$2:$B$722,8,Данные!$C$2:$C$722,1,Данные!$A$2:$A$722,">="&7723950000,Данные!$A$2:$A$722,"<="&7723951099) -> 0 | BR6: =COUNTIFS(Данные!$B$2:$B$722,8,Данные!$C$2:$C$722,1,Данные!$A$2:$A$722,">="&7723020000,Данные!$A$2:$A$722,"<="&7723020999) -> 0 | BS6: =COUNTIFS(Данные!$B$2:$B$722,8,Данные!$C$2:$C$722,1,Данные!$A$2:$A$722,">="&7723029000,Данные!$A$2:$A$722,"<="&7723029999) -> 0 | BT6: =COUNTIFS(Данные!$B$2:$B$722,8,Данные!$C$2:$C$722,1,Данные!$A$2:$A$722,">="&7723055000,Данные!$A$2:$A$722,"<="&7723056549) -> 0 | BU6: =COUNTIFS(Данные!$B$2:$B$722,8,Данные!$C$2:$C$722,1,Данные!$A$2:$A$722,">="&7725250000,Данные!$A$2:$A$722,"<="&7725250499) -> 0 | BV6: =COUNTIFS(Данные!$B$2:$B$722,8,Данные!$C$2:$C$722,1,Данные!$A$2:$A$722,">="&7183841400,Данные!$A$2:$A$722,"<="&7183841499) -> 0 | BW6: 300 | BX6: =F6-BW6 -> -300
C7: 2 | D7: 82 | F7: =COUNTIFS(Данные!$B$2:$B$722,8,Данные!$C$2:$C$722,2) -> 0 | G7: =COUNTIFS(Данные!$B$2:$B$722,8,Данные!$C$2:$C$722,2,Данные!$A$2:$A$722,">="&77232210840,Данные!$A$2:$A$722,"<="&77232216999) -> 0 | H7: =COUNTIFS(Данные!$B$2:$B$722,8,Данные!$C$2:$C$722,2,Данные!$A$2:$A$722,">="&77232510512,Данные!$A$2:$A$722,"<="&77232519487) -> 0 | I7: =COUNTIFS(Данные!$B$2:$B$722,8,Данные!$C$2:$C$722,2,Данные!$A$2:$A$722,">="&77232524160,Данные!$A$2:$A$722,"<="&77232529999) -> 0 | J7: =COUNTIFS(Данные!$B$2:$B$722,8,Данные!$C$2:$C$722,2,Данные!$A$2:$A$722,">="&77232544000,Данные!$A$2:$A$722,"<="&77232544999) -> 0 | K7: =COUNTIFS(Данные!$B$2:$B$722,8,Данные!$C$2:$C$722,2,Данные!$A$2:$A$722,">="&77232295504,Данные!$A$2:$A$722,"<="&77232296999) -> 0 | L7: =COUNTIFS(Данные!$B$2:$B$722,8,Данные!$C$2:$C$722,2,Данные!$A$2:$A$722,">="&77232785000,Данные!$A$2:$A$722,"<="&77232789999) -> 0 | M7: =COUNTIFS(Данные!$B$2:$B$722,8,Данные!$C$2:$C$722,2,Данные!$A$2:$A$722,">="&77233150000,Данные!$A$2:$A$722,"<="&77233155999) -> 0 | N7: =COUNTIFS(Данные!$B$2:$B$722,8,Данные!$C$2:$C$722,2,Данные!$A$2:$A$722,">="&77233235000,Данные!$A$2:$A$722,"<="&77233235999) -> 0 | O7: =COUNTIFS(Данные!$B$2:$B$722,8,Данные!$C$2:$C$722,2,Данные!$A$2:$A$722,">="&77233239000,Данные!$A$2:$A$722,"<="&77233239999) -> 0 | P7: =COUNTIFS(Данные!$B$2:$B$722,8,Данные!$C$2:$C$722,2,Данные!$A$2:$A$722,">="&77233272000,Данные!$A$2:$A$722,"<="&77233272999) -> 0 | Q7: =COUNTIFS(Данные!$B$2:$B$722,8,Данные!$C$2:$C$722,2,Данные!$A$2:$A$722,">="&77233291100,Данные!$A$2:$A$722,"<="&77233292999) -> 0 | R7: =COUNTIFS(Данные!$B$2:$B$722,8,Данные!$C$2:$C$722,2,Данные!$A$2:$A$722,">="&77233297000,Данные!$A$2:$A$722,"<="&77233298399) -> 0 | S7: =COUNTIFS(Данные!$B$2:$B$722,8,Данные!$C$2:$C$722,2,Данные!$A$2:$A$722,">="&77235124000,Данные!$A$2:$A$722,"<="&77235128499) -> 0 | T7: =COUNTIFS(Данные!$B$2:$B$722,8,Данные!$C$2:$C$722,2,Данные!$A$2:$A$722,">="&77235320000,Данные!$A$2:$A$722,"<="&77235320999) -> 0 | U7: =COUNTIFS(Данные!$B$2:$B$722,8,Данные!$C$2:$C$722,2,Данные!$A$2:$A$722,">="&77233620000,Данные!$A$2:$A$722,"<="&77233623339) -> 0 | V7: =COUNTIFS(Данные!$B$2:$B$722,8,Данные!$C$2:$C$722,2,Данные!$A$2:$A$722,">="&77233630000,Данные!$A$2:$A$722,"<="&77233630999) -> 0 | W7: =COUNTIFS(Данные!$B$2:$B$722,8,Данные!$C$2:$C$722,2,Данные!$A$2:$A$722,">="&77233637000,Данные!$A$2:$A$722,"<="&77233637599) -> 0 | X7: =COUNTIFS(Данные!$B$2:$B$722,8,Данные!$C$2:$C$722,2,Данные!$A$2:$A$722,">="&77233550000,Данные!$A$2:$A$722,"<="&77233550999) -> 0 | Y7: =COUNTIFS(Данные!$B$2:$B$722,8,Данные!$C$2:$C$722,2,Данные!$A$2:$A$722,">="&77233554000,Данные!$A$2:$A$722,"<="&77233554999) -> 0 | Z7: =COUNTIFS(Данные!$B$2:$B$722,8,Данные!$C$2:$C$722,2,Данные!$A$2:$A$722,">="&77233555000,Данные!$A$2:$A$722,"<="&77233556999) -> 0 | AA7: =COUNTIFS(Данные!$B$2:$B$722,8,Данные!$C$2:$C$722,2,Данные!$A$2:$A$722,">="&77233726000,Данные!$A$2:$A$722,"<="&77233726999) -> 0 | AB7: =COUNTIFS(Данные!$B$2:$B$722,8,Данные!$C$2:$C$722,2,Данные!$A$2:$A$722,">="&77233820000,Данные!$A$2:$A$722,"<="&77233820999) -> 0 | AC7: =COUNTIFS(Данные!$B$2:$B$722,8,Данные!$C$2:$C$722,2,Данные!$A$2:$A$722,">="&77233850000,Данные!$A$2:$A$722,"<="&77233850999) -> 0 | AD7: =COUNTIFS(Данные!$B$2:$B$722,8,Данные!$C$2:$C$722,2,Данные!$A$2:$A$722,">="&77233420000,Данные!$A$2:$A$722,"<="&77233420999) -> 0 | AE7: =COUNTIFS(Данные!$B$2:$B$722,8,Данные!$C$2:$C$722,2,Данные!$A$2:$A$722,">="&77234740000,Данные!$A$2:$A$722,"<="&77234742999) -> 0 | AF7: =COUNTIFS(Данные!$B$2:$B$722,8,Данные!$C$2:$C$722,2,Данные!$A$2:$A$722,">="&77234767000,Данные!$A$2:$A$722,"<="&77234767999) -> 0 | AG7: =COUNTIFS(Данные!$B$2:$B$722,8,Данные!$C$2:$C$722,2,Данные!$A$2:$A$722,">="&77234120000,Данные!$A$2:$A$722,"<="&77234120999) -> 0 | AH7: =COUNTIFS(Данные!$B$2:$B$722,8,Данные!$C$2:$C$722,2,Данные!$A$2:$A$722,">="&77234127000,Данные!$A$2:$A$722,"<="&77234127999) -> 0 | AI7: =COUNTIFS(Данные!$B$2:$B$722,8,Данные!$C$2:$C$722,2,Данные!$A$2:$A$722,">="&77234220000,Данные!$A$2:$A$722,"<="&77234220999) -> 0 | AJ7: =COUNTIFS(Данные!$B$2:$B$722,8,Данные!$C$2:$C$722,2,Данные!$A$2:$A$722,">="&77234250000,Данные!$A$2:$A$722,"<="&77234250999) -> 0 | AK7: =COUNTIFS(Данные!$B$2:$B$722,8,Данные!$C$2:$C$722,2,Данные!$A$2:$A$722,">="&77233922950,Данные!$A$2:$A$722,"<="&77233924999) -> 0 | AL7: =COUNTIFS(Данные!$B$2:$B$722,8,Данные!$C$2:$C$722,2,Данные!$A$2:$A$722,">="&77234320000,Данные!$A$2:$A$722,"<="&77234320999) -> 0 | AM7: =COUNTIFS(Данные!$B$2:$B$722,8,Данные!$C$2:$C$722,2,Данные!$A$2:$A$722,">="&77234350000,Данные!$A$2:$A$722,"<="&77234350999) -> 0 | AN7: =COUNTIFS(Данные!$B$2:$B$722,8,Данные!$C$2:$C$722,2,Данные!$A$2:$A$722,">="&77234020000,Данные!$A$2:$A$722,"<="&77234020999) -> 0 | AO7: =COUNTIFS(Данные!$B$2:$B$722,8,Данные!$C$2:$C$722,2,Данные!$A$2:$A$722,">="&77234029000,Данные!$A$2:$A$722,"<="&77234029999) -> 0 | AP7: =COUNTIFS(Данные!$B$2:$B$722,8,Данные!$C$2:$C$722,2,Данные!$A$2:$A$722,">="&77234050000,Данные!$A$2:$A$722,"<="&77234050999) -> 0 | AQ7: =COUNTIFS(Данные!$B$2:$B$722,8,Данные!$C$2:$C$722,2,Данные!$A$2:$A$722,">="&77234427000,Данные!$A$2:$A$722,"<="&77234428999) -> 0 | AR7: =COUNTIFS(Данные!$B$2:$B$722,8,Данные!$C$2:$C$722,2,Данные!$A$2:$A$722,">="&77234450000,Данные!$A$2:$A$722,"<="&77234450999) -> 0 | AS7: =COUNTIFS(Данные!$B$2:$B$722,8,Данные!$C$2:$C$722,2,Данные!$A$2:$A$722,">="&77234620000,Данные!$A$2:$A$722,"<="&77234620999) -> 0 | AT7: =COUNTIFS(Данные!$B$2:$B$722,8,Данные!$C$2:$C$722,2,Данные!$A$2:$A$722,">="&77234650000,Данные!$A$2:$A$722,"<="&77234650999) -> 0 | AU7: =COUNTIFS(Данные!$B$2:$B$722,8,Данные!$C$2:$C$722,2,Данные!$A$2:$A$722,">="&77234820000,Данные!$A$2:$A$722,"<="&77234820999) -> 0 | AV7: =COUNTIFS(Данные!$B$2:$B$722,8,Данные!$C$2:$C$722,2,Данные!$A$2:$A$722,">="&77234850000,Данные!$A$2:$A$722,"<="&77234850999) -> 0 | AW7: =COUNTIFS(Данные!$B$2:$B$722,8,Данные!$C$2:$C$722,2,Данные!$A$2:$A$722,">="&77233327000,Данные!$A$2:$A$722,"<="&77233327999) -> 0 | AX7: =COUNTIFS(Данные!$B$2:$B$722,8,Данные!$C$2:$C$722,2,Данные!$A$2:$A$722,">="&77233350000,Данные!$A$2:$A$722,"<="&77233350599) -> 0 | AY7: =COUNTIFS(Данные!$B$2:$B$722,8,Данные!$C$2:$C$722,2,Данные!$A$2:$A$722,">="&77233351000,Данные!$A$2:$A$722,"<="&77233351999) -> 0 | AZ7: =COUNTIFS(Данные!$B$2:$B$722,8,Данные!$C$2:$C$722,2,Данные!$A$2:$A$722,">="&7722440000,Данные!$A$2:$A$722,"<="&7722440999) -> 0 | BA7: =COUNTIFS(Данные!$B$2:$B$722,8,Данные!$C$2:$C$722,2,Данные!$A$2:$A$722,">="&7722442000,Данные!$A$2:$A$722,"<="&7722445659) -> 0 | BB7: =COUNTIFS(Данные!$B$2:$B$722,8,Данные!$C$2:$C$722,2,Данные!$A$2:$A$722,">="&7722450000,Данные!$A$2:$A$722,"<="&7722450199) -> 0 | BC7: =COUNTIFS(Данные!$B$2:$B$722,8,Данные!$C$2:$C$722,2,Данные!$A$2:$A$722,">="&7722451000,Данные!$A$2:$A$722,"<="&7722451374) -> 0 | BD7: =COUNTIFS(Данные!$B$2:$B$722,8,Данные!$C$2:$C$722,2,Данные!$A$2:$A$722,">="&7722452000,Данные!$A$2:$A$722,"<="&7722452299) -> 0 | BE7: =COUNTIFS(Данные!$B$2:$B$722,8,Данные!$C$2:$C$722,2,Данные!$A$2:$A$722,">="&7722453000,Данные!$A$2:$A$722,"<="&7722453816) -> 0 | BF7: =COUNTIFS(Данные!$B$2:$B$722,8,Данные!$C$2:$C$722,2,Данные!$A$2:$A$722,">="&7722454000,Данные!$A$2:$A$722,"<="&7722454099) -> 0 | BG7: =COUNTIFS(Данные!$B$2:$B$722,8,Данные!$C$2:$C$722,2,Данные!$A$2:$A$722,">="&7722458000,Данные!$A$2:$A$722,"<="&7722458999) -> 0 | BH7: =COUNTIFS(Данные!$B$2:$B$722,8,Данные!$C$2:$C$722,2,Данные!$A$2:$A$722,">="&7722630000,Данные!$A$2:$A$722,"<="&7722638549) -> 0 | BI7: =COUNTIFS(Данные!$B$2:$B$722,8,Данные!$C$2:$C$722,2,Данные!$A$2:$A$722,">="&7722639400,Данные!$A$2:$A$722,"<="&7722639899) -> 0 | BJ7: =COUNTIFS(Данные!$B$2:$B$722,8,Данные!$C$2:$C$722,2,Данные!$A$2:$A$722,">="&7725750000,Данные!$A$2:$A$722,"<="&7725750399) -> 0 | BK7: =COUNTIFS(Данные!$B$2:$B$722,8,Данные!$C$2:$C$722,2,Данные!$A$2:$A$722,">="&7723620000,Данные!$A$2:$A$722,"<="&7723621299) -> 0 | BL7: =COUNTIFS(Данные!$B$2:$B$722,8,Данные!$C$2:$C$722,2,Данные!$A$2:$A$722,">="&7723621600,Данные!$A$2:$A$722,"<="&7723623399) -> 0 | BM7: =COUNTIFS(Данные!$B$2:$B$722,8,Данные!$C$2:$C$722,2,Данные!$A$2:$A$722,">="&7725127000,Данные!$A$2:$A$722,"<="&7725127999) -> 0 | BN7: =COUNTIFS(Данные!$B$2:$B$722,8,Данные!$C$2:$C$722,2,Данные!$A$2:$A$722,">="&7723772000,Данные!$A$2:$A$722,"<="&7723724999) -> 0 | BO7: =COUNTIFS(Данные!$B$2:$B$722,8,Данные!$C$2:$C$722,2,Данные!$A$2:$A$722,">="&7723765000,Данные!$A$2:$A$722,"<="&7723765499) -> 0 | BP7: =COUNTIFS(Данные!$B$2:$B$722,8,Данные!$C$2:$C$722,2,Данные!$A$2:$A$722,">="&7723948000,Данные!$A$2:$A$722,"<="&7723948999) -> 0 | BQ7: =COUNTIFS(Данные!$B$2:$B$722,8,Данные!$C$2:$C$722,2,Данные!$A$2:$A$722,">="&7723950000,Данные!$A$2:$A$722,"<="&7723951099) -> 0 | BR7: =COUNTIFS(Данные!$B$2:$B$722,8,Данные!$C$2:$C$722,2,Данные!$A$2:$A$722,">="&7723020000,Данные!$A$2:$A$722,"<="&7723020999) -> 0 | BS7: =COUNTIFS(Данные!$B$2:$B$722,8,Данные!$C$2:$C$722,2,Данные!$A$2:$A$722,">="&7723029000,Данные!$A$2:$A$722,"<="&7723029999) -> 0 | BT7: =COUNTIFS(Данные!$B$2:$B$722,8,Данные!$C$2:$C$722,2,Данные!$A$2:$A$722,">="&7723055000,Данные!$A$2:$A$722,"<="&7723056549) -> 0 | BU7: =COUNTIFS(Данные!$B$2:$B$722,8,Данные!$C$2:$C$722,2,Данные!$A$2:$A$722,">="&7725250000,Данные!$A$2:$A$722,"<="&7725250499) -> 0 | BV7: =COUNTIFS(Данные!$B$2:$B$722,8,Данные!$C$2:$C$722,2,Данные!$A$2:$A$722,">="&7183841400,Данные!$A$2:$A$722,"<="&7183841499) -> 0 | BW7: 300 | BX7: =F7-BW7 -> -300
A8: 9 | B8: Шемонаиха | C8: 0 | D8: 90 | E8: =SUM(F8:F10) -> 64 | F8: =COUNTIFS(Данные!$B$2:$B$722,9,Данные!$C$2:$C$722,0) -> 0 | G8: =COUNTIFS(Данные!$B$2:$B$722,9,Данные!$C$2:$C$722,0,Данные!$A$2:$A$722,">="&77232210840,Данные!$A$2:$A$722,"<="&77232216999) -> 0 | H8: =COUNTIFS(Данные!$B$2:$B$722,9,Данные!$C$2:$C$722,0,Данные!$A$2:$A$722,">="&77232510512,Данные!$A$2:$A$722,"<="&77232519487) -> 0 | I8: =COUNTIFS(Данные!$B$2:$B$722,9,Данные!$C$2:$C$722,0,Данные!$A$2:$A$722,">="&77232524160,Данные!$A$2:$A$722,"<="&77232529999) -> 0 | J8: =COUNTIFS(Данные!$B$2:$B$722,9,Данные!$C$2:$C$722,0,Данные!$A$2:$A$722,">="&77232544000,Данные!$A$2:$A$722,"<="&77232544999) -> 0 | K8: =COUNTIFS(Данные!$B$2:$B$722,9,Данные!$C$2:$C$722,0,Данные!$A$2:$A$722,">="&77232295504,Данные!$A$2:$A$722,"<="&77232296999) -> 0 | L8: =COUNTIFS(Данные!$B$2:$B$722,9,Данные!$C$2:$C$722,0,Данные!$A$2:$A$722,">="&77232785000,Данные!$A$2:$A$722,"<="&77232789999) -> 0 | M8: =COUNTIFS(Данные!$B$2:$B$722,9,Данные!$C$2:$C$722,0,Данные!$A$2:$A$722,">="&77233150000,Данные!$A$2:$A$722,"<="&77233155999) -> 0 | N8: =COUNTIFS(Данные!$B$2:$B$722,9,Данные!$C$2:$C$722,0,Данные!$A$2:$A$722,">="&77233235000,Данные!$A$2:$A$722,"<="&77233235999) -> 0 | O8: =COUNTIFS(Данные!$B$2:$B$722,9,Данные!$C$2:$C$722,0,Данные!$A$2:$A$722,">="&77233239000,Данные!$A$2:$A$722,"<="&77233239999) -> 0 | P8: =COUNTIFS(Данные!$B$2:$B$722,9,Данные!$C$2:$C$722,0,Данные!$A$2:$A$722,">="&77233272000,Данные!$A$2:$A$722,"<="&77233272999) -> 0 | Q8: =COUNTIFS(Данные!$B$2:$B$722,9,Данные!$C$2:$C$722,0,Данные!$A$2:$A$722,">="&77233291100,Данные!$A$2:$A$722,"<="&77233292999) -> 0 | R8: =COUNTIFS(Данные!$B$2:$B$722,9,Данные!$C$2:$C$722,0,Данные!$A$2:$A$722,">="&77233297000,Данные!$A$2:$A$722,"<="&77233298399) -> 0 | S8: =COUNTIFS(Данные!$B$2:$B$722,9,Данные!$C$2:$C$722,0,Данные!$A$2:$A$722,">="&77235124000,Данные!$A$2:$A$722,"<="&77235128499) -> 0 | T8: =COUNTIFS(Данные!$B$2:$B$722,9,Данные!$C$2:$C$722,0,Данные!$A$2:$A$722,">="&77235320000,Данные!$A$2:$A$722,"<="&77235320999) -> 0 | U8: =COUNTIFS(Данные!$B$2:$B$722,9,Данные!$C$2:$C$722,0,Данные!$A$2:$A$722,">="&77233620000,Данные!$A$2:$A$722,"<="&77233623339) -> 0 | V8: =COUNTIFS(Данные!$B$2:$B$722,9,Данные!$C$2:$C$722,0,Данные!$A$2:$A$722,">="&77233630000,Данные!$A$2:$A$722,"<="&77233630999) -> 0 | W8: =COUNTIFS(Данные!$B$2:$B$722,9,Данные!$C$2:$C$722,0,Данные!$A$2:$A$722,">="&77233637000,Данные!$A$2:$A$722,"<="&77233637599) -> 0 | X8: =COUNTIFS(Данные!$B$2:$B$722,9,Данные!$C$2:$C$722,0,Данные!$A$2:$A$722,">="&77233550000,Данные!$A$2:$A$722,"<="&77233550999) -> 0 | Y8: =COUNTIFS(Данные!$B$2:$B$722,9,Данные!$C$2:$C$722,0,Данные!$A$2:$A$722,">="&77233554000,Данные!$A$2:$A$722,"<="&77233554999) -> 0 | Z8: =COUNTIFS(Данные!$B$2:$B$722,9,Данные!$C$2:$C$722,0,Данные!$A$2:$A$722,">="&77233555000,Данные!$A$2:$A$722,"<="&77233556999) -> 0 | AA8: =COUNTIFS(Данные!$B$2:$B$722,9,Данные!$C$2:$C$722,0,Данные!$A$2:$A$722,">="&77233726000,Данные!$A$2:$A$722,"<="&77233726999) -> 0 | AB8: =COUNTIFS(Данные!$B$2:$B$722,9,Данные!$C$2:$C$722,0,Данные!$A$2:$A$722,">="&77233820000,Данные!$A$2:$A$722,"<="&77233820999) -> 0 | AC8: =COUNTIFS(Данные!$B$2:$B$722,9,Данные!$C$2:$C$722,0,Данные!$A$2:$A$722,">="&77233850000,Данные!$A$2:$A$722,"<="&77233850999) -> 0 | AD8: =COUNTIFS(Данные!$B$2:$B$722,9,Данные!$C$2:$C$722,0,Данные!$A$2:$A$722,">="&77233420000,Данные!$A$2:$A$722,"<="&77233420999) -> 0 | AE8: =COUNTIFS(Данные!$B$2:$B$722,9,Данные!$C$2:$C$722,0,Данные!$A$2:$A$722,">="&77234740000,Данные!$A$2:$A$722,"<="&77234742999) -> 0 | AF8: =COUNTIFS(Данные!$B$2:$B$722,9,Данные!$C$2:$C$722,0,Данные!$A$2:$A$722,">="&77234767000,Данные!$A$2:$A$722,"<="&77234767999) -> 0 | AG8: =COUNTIFS(Данные!$B$2:$B$722,9,Данные!$C$2:$C$722,0,Данные!$A$2:$A$722,">="&77234120000,Данные!$A$2:$A$722,"<="&77234120999) -> 0 | AH8: =COUNTIFS(Данные!$B$2:$B$722,9,Данные!$C$2:$C$722,0,Данные!$A$2:$A$722,">="&77234127000,Данные!$A$2:$A$722,"<="&77234127999) -> 0 | AI8: =COUNTIFS(Данные!$B$2:$B$722,9,Данные!$C$2:$C$722,0,Данные!$A$2:$A$722,">="&77234220000,Данные!$A$2:$A$722,"<="&77234220999) -> 0 | AJ8: =COUNTIFS(Данные!$B$2:$B$722,9,Данные!$C$2:$C$722,0,Данные!$A$2:$A$722,">="&77234250000,Данные!$A$2:$A$722,"<="&77234250999) -> 0 | AK8: =COUNTIFS(Данные!$B$2:$B$722,9,Данные!$C$2:$C$722,0,Данные!$A$2:$A$722,">="&77233922950,Данные!$A$2:$A$722,"<="&77233924999) -> 0 | AL8: =COUNTIFS(Данные!$B$2:$B$722,9,Данные!$C$2:$C$722,0,Данные!$A$2:$A$722,">="&77234320000,Данные!$A$2:$A$722,"<="&77234320999) -> 0 | AM8: =COUNTIFS(Данные!$B$2:$B$722,9,Данные!$C$2:$C$722,0,Данные!$A$2:$A$722,">="&77234350000,Данные!$A$2:$A$722,"<="&77234350999) -> 0 | AN8: =COUNTIFS(Данные!$B$2:$B$722,9,Данные!$C$2:$C$722,0,Данные!$A$2:$A$722,">="&77234020000,Данные!$A$2:$A$722,"<="&77234020999) -> 0 | AO8: =COUNTIFS(Данные!$B$2:$B$722,9,Данные!$C$2:$C$722,0,Данные!$A$2:$A$722,">="&77234029000,Данные!$A$2:$A$722,"<="&77234029999) -> 0 | AP8: =COUNTIFS(Данные!$B$2:$B$722,9,Данные!$C$2:$C$722,0,Данные!$A$2:$A$722,">="&77234050000,Данные!$A$2:$A$722,"<="&77234050999) -> 0 | AQ8: =COUNTIFS(Данные!$B$2:$B$722,9,Данные!$C$2:$C$722,0,Данные!$A$2:$A$722,">="&77234427000,Данные!$A$2:$A$722,"<="&77234428999) -> 0 | AR8: =COUNTIFS(Данные!$B$2:$B$722,9,Данные!$C$2:$C$722,0,Данные!$A$2:$A$722,">="&77234450000,Данные!$A$2:$A$722,"<="&77234450999) -> 0 | AS8: =COUNTIFS(Данные!$B$2:$B$722,9,Данные!$C$2:$C$722,0,Данные!$A$2:$A$722,">="&77234620000,Данные!$A$2:$A$722,"<="&77234620999) -> 0 | AT8: =COUNTIFS(Данные!$B$2:$B$722,9,Данные!$C$2:$C$722,0,Данные!$A$2:$A$722,">="&77234650000,Данные!$A$2:$A$722,"<="&77234650999) -> 0 | AU8: =COUNTIFS(Данные!$B$2:$B$722,9,Данные!$C$2:$C$722,0,Данные!$A$2:$A$722,">="&77234820000,Данные!$A$2:$A$722,"<="&77234820999) -> 0 | AV8: =COUNTIFS(Данные!$B$2:$B$722,9,Данные!$C$2:$C$722,0,Данные!$A$2:$A$722,">="&77234850000,Данные!$A$2:$A$722,"<="&77234850999) -> 0 | AW8: =COUNTIFS(Данные!$B$2:$B$722,9,Данные!$C$2:$C$722,0,Данные!$A$2:$A$722,">="&77233327000,Данные!$A$2:$A$722,"<="&77233327999) -> 0 | AX8: =COUNTIFS(Данные!$B$2:$B$722,9,Данные!$C$2:$C$722,0,Данные!$A$2:$A$722,">="&77233350000,Данные!$A$2:$A$722,"<="&77233350599) -> 0 | AY8: =COUNTIFS(Данные!$B$2:$B$722,9,Данные!$C$2:$C$722,0,Данные!$A$2:$A$722,">="&77233351000,Данные!$A$2:$A$722,"<="&77233351999) -> 0 | AZ8: =COUNTIFS(Данные!$B$2:$B$722,9,Данные!$C$2:$C$722,0,Данные!$A$2:$A$722,">="&7722440000,Данные!$A$2:$A$722,"<="&7722440999) -> 0 | BA8: =COUNTIFS(Данные!$B$2:$B$722,9,Данные!$C$2:$C$722,0,Данные!$A$2:$A$722,">="&7722442000,Данные!$A$2:$A$722,"<="&7722445659) -> 0 | BB8: =COUNTIFS(Данные!$B$2:$B$722,9,Данные!$C$2:$C$722,0,Данные!$A$2:$A$722,">="&7722450000,Данные!$A$2:$A$722,"<="&7722450199) -> 0 | BC8: =COUNTIFS(Данные!$B$2:$B$722,9,Данные!$C$2:$C$722,0,Данные!$A$2:$A$722,">="&7722451000,Данные!$A$2:$A$722,"<="&7722451374) -> 0 | BD8: =COUNTIFS(Данные!$B$2:$B$722,9,Данные!$C$2:$C$722,0,Данные!$A$2:$A$722,">="&7722452000,Данные!$A$2:$A$722,"<="&7722452299) -> 0 | BE8: =COUNTIFS(Данные!$B$2:$B$722,9,Данные!$C$2:$C$722,0,Данные!$A$2:$A$722,">="&7722453000,Данные!$A$2:$A$722,"<="&7722453816) -> 0 | BF8: =COUNTIFS(Данные!$B$2:$B$722,9,Данные!$C$2:$C$722,0,Данные!$A$2:$A$722,">="&7722454000,Данные!$A$2:$A$722,"<="&7722454099) -> 0 | BG8: =COUNTIFS(Данные!$B$2:$B$722,9,Данные!$C$2:$C$722,0,Данные!$A$2:$A$722,">="&7722458000,Данные!$A$2:$A$722,"<="&7722458999) -> 0 | BH8: =COUNTIFS(Данные!$B$2:$B$722,9,Данные!$C$2:$C$722,0,Данные!$A$2:$A$722,">="&7722630000,Данные!$A$2:$A$722,"<="&7722638549) -> 0 | BI8: =COUNTIFS(Данные!$B$2:$B$722,9,Данные!$C$2:$C$722,0,Данные!$A$2:$A$722,">="&7722639400,Данные!$A$2:$A$722,"<="&7722639899) -> 0 | BJ8: =COUNTIFS(Данные!$B$2:$B$722,9,Данные!$C$2:$C$722,0,Данные!$A$2:$A$722,">="&7725750000,Данные!$A$2:$A$722,"<="&7725750399) -> 0 | BK8: =COUNTIFS(Данные!$B$2:$B$722,9,Данные!$C$2:$C$722,0,Данные!$A$2:$A$722,">="&7723620000,Данные!$A$2:$A$722,"<="&7723621299) -> 0 | BL8: =COUNTIFS(Данные!$B$2:$B$722,9,Данные!$C$2:$C$722,0,Данные!$A$2:$A$722,">="&7723621600,Данные!$A$2:$A$722,"<="&7723623399) -> 0 | BM8: =COUNTIFS(Данные!$B$2:$B$722,9,Данные!$C$2:$C$722,0,Данные!$A$2:$A$722,">="&7725127000,Данные!$A$2:$A$722,"<="&7725127999) -> 0 | BN8: =COUNTIFS(Данные!$B$2:$B$722,9,Данные!$C$2:$C$722,0,Данные!$A$2:$A$722,">="&7723772000,Данные!$A$2:$A$722,"<="&7723724999) -> 0 | BO8: =COUNTIFS(Данные!$B$2:$B$722,9,Данные!$C$2:$C$722,0,Данные!$A$2:$A$722,">="&7723765000,Данные!$A$2:$A$722,"<="&7723765499) -> 0 | BP8: =COUNTIFS(Данные!$B$2:$B$722,9,Данные!$C$2:$C$722,0,Данные!$A$2:$A$722,">="&7723948000,Данные!$A$2:$A$722,"<="&7723948999) -> 0 | BQ8: =COUNTIFS(Данные!$B$2:$B$722,9,Данные!$C$2:$C$722,0,Данные!$A$2:$A$722,">="&7723950000,Данные!$A$2:$A$722,"<="&7723951099) -> 0 | BR8: =COUNTIFS(Данные!$B$2:$B$722,9,Данные!$C$2:$C$722,0,Данные!$A$2:$A$722,">="&7723020000,Данные!$A$2:$A$722,"<="&7723020999) -> 0 | BS8: =COUNTIFS(Данные!$B$2:$B$722,9,Данные!$C$2:$C$722,0,Данные!$A$2:$A$722,">="&7723029000,Данные!$A$2:$A$722,"<="&7723029999) -> 0 | BT8: =COUNTIFS(Данные!$B$2:$B$722,9,Данные!$C$2:$C$722,0,Данные!$A$2:$A$722,">="&7723055000,Данные!$A$2:$A$722,"<="&7723056549) -> 0 | BU8: =COUNTIFS(Данные!$B$2:$B$722,9,Данные!$C$2:$C$722,0,Данные!$A$2:$A$722,">="&7725250000,Данные!$A$2:$A$722,"<="&7725250499) -> 0 | BV8: =COUNTIFS(Данные!$B$2:$B$722,9,Данные!$C$2:$C$722,0,Данные!$A$2:$A$722,">="&7183841400,Данные!$A$2:$A$722,"<="&7183841499) -> 0 | BW8: 300 | BX8: =F8-BW8 -> -300
C9: 1 | D9: 91 | F9: =COUNTIFS(Данные!$B$2:$B$722,9,Данные!$C$2:$C$722,1) -> 64 | G9: =COUNTIFS(Данные!$B$2:$B$722,9,Данные!$C$2:$C$722,1,Данные!$A$2:$A$722,">="&77232210840,Данные!$A$2:$A$722,"<="&77232216999) -> 0 | H9: =COUNTIFS(Данные!$B$2:$B$722,9,Данные!$C$2:$C$722,1,Данные!$A$2:$A$722,">="&77232510512,Данные!$A$2:$A$722,"<="&77232519487) -> 0 | I9: =COUNTIFS(Данные!$B$2:$B$722,9,Данные!$C$2:$C$722,1,Данные!$A$2:$A$722,">="&77232524160,Данные!$A$2:$A$722,"<="&77232529999) -> 0 | J9: =COUNTIFS(Данные!$B$2:$B$722,9,Данные!$C$2:$C$722,1,Данные!$A$2:$A$722,">="&77232544000,Данные!$A$2:$A$722,"<="&77232544999) -> 0 | K9: =COUNTIFS(Данные!$B$2:$B$722,9,Данные!$C$2:$C$722,1,Данные!$A$2:$A$722,">="&77232295504,Данные!$A$2:$A$722,"<="&77232296999) -> 0 | L9: =COUNTIFS(Данные!$B$2:$B$722,9,Данные!$C$2:$C$722,1,Данные!$A$2:$A$722,">="&77232785000,Данные!$A$2:$A$722,"<="&77232789999) -> 0 | M9: =COUNTIFS(Данные!$B$2:$B$722,9,Данные!$C$2:$C$722,1,Данные!$A$2:$A$722,">="&77233150000,Данные!$A$2:$A$722,"<="&77233155999) -> 0 | N9: =COUNTIFS(Данные!$B$2:$B$722,9,Данные!$C$2:$C$722,1,Данные!$A$2:$A$722,">="&77233235000,Данные!$A$2:$A$722,"<="&77233235999) -> 0 | O9: =COUNTIFS(Данные!$B$2:$B$722,9,Данные!$C$2:$C$722,1,Данные!$A$2:$A$722,">="&77233239000,Данные!$A$2:$A$722,"<="&77233239999) -> 0 | P9: =COUNTIFS(Данные!$B$2:$B$722,9,Данные!$C$2:$C$722,1,Данные!$A$2:$A$722,">="&77233272000,Данные!$A$2:$A$722,"<="&77233272999) -> 0 | Q9: =COUNTIFS(Данные!$B$2:$B$722,9,Данные!$C$2:$C$722,1,Данные!$A$2:$A$722,">="&77233291100,Данные!$A$2:$A$722,"<="&77233292999) -> 0 | R9: =COUNTIFS(Данные!$B$2:$B$722,9,Данные!$C$2:$C$722,1,Данные!$A$2:$A$722,">="&77233297000,Данные!$A$2:$A$722,"<="&77233298399) -> 0 | S9: =COUNTIFS(Данные!$B$2:$B$722,9,Данные!$C$2:$C$722,1,Данные!$A$2:$A$722,">="&77235124000,Данные!$A$2:$A$722,"<="&77235128499) -> 0 | T9: =COUNTIFS(Данные!$B$2:$B$722,9,Данные!$C$2:$C$722,1,Данные!$A$2:$A$722,">="&77235320000,Данные!$A$2:$A$722,"<="&77235320999) -> 62 | U9: =COUNTIFS(Данные!$B$2:$B$722,9,Данные!$C$2:$C$722,1,Данные!$A$2:$A$722,">="&77233620000,Данные!$A$2:$A$722,"<="&77233623339) -> 0 | V9: =COUNTIFS(Данные!$B$2:$B$722,9,Данные!$C$2:$C$722,1,Данные!$A$2:$A$722,">="&77233630000,Данные!$A$2:$A$722,"<="&77233630999) -> 0 | W9: =COUNTIFS(Данные!$B$2:$B$722,9,Данные!$C$2:$C$722,1,Данные!$A$2:$A$722,">="&77233637000,Данные!$A$2:$A$722,"<="&77233637599) -> 0 | X9: =COUNTIFS(Данные!$B$2:$B$722,9,Данные!$C$2:$C$722,1,Данные!$A$2:$A$722,">="&77233550000,Данные!$A$2:$A$722,"<="&77233550999) -> 0 | Y9: =COUNTIFS(Данные!$B$2:$B$722,9,Данные!$C$2:$C$722,1,Данные!$A$2:$A$722,">="&77233554000,Данные!$A$2:$A$722,"<="&77233554999) -> 0 | Z9: =COUNTIFS(Данные!$B$2:$B$722,9,Данные!$C$2:$C$722,1,Данные!$A$2:$A$722,">="&77233555000,Данные!$A$2:$A$722,"<="&77233556999) -> 0 | AA9: =COUNTIFS(Данные!$B$2:$B$722,9,Данные!$C$2:$C$722,1,Данные!$A$2:$A$722,">="&77233726000,Данные!$A$2:$A$722,"<="&77233726999) -> 0 | AB9: =COUNTIFS(Данные!$B$2:$B$722,9,Данные!$C$2:$C$722,1,Данные!$A$2:$A$722,">="&77233820000,Данные!$A$2:$A$722,"<="&77233820999) -> 0 | AC9: =COUNTIFS(Данные!$B$2:$B$722,9,Данные!$C$2:$C$722,1,Данные!$A$2:$A$722,">="&77233850000,Данные!$A$2:$A$722,"<="&77233850999) -> 0 | AD9: =COUNTIFS(Данные!$B$2:$B$722,9,Данные!$C$2:$C$722,1,Данные!$A$2:$A$722,">="&77233420000,Данные!$A$2:$A$722,"<="&77233420999) -> 0 | AE9: =COUNTIFS(Данные!$B$2:$B$722,9,Данные!$C$2:$C$722,1,Данные!$A$2:$A$722,">="&77234740000,Данные!$A$2:$A$722,"<="&77234742999) -> 0 | AF9: =COUNTIFS(Данные!$B$2:$B$722,9,Данные!$C$2:$C$722,1,Данные!$A$2:$A$722,">="&77234767000,Данные!$A$2:$A$722,"<="&77234767999) -> 0 | AG9: =COUNTIFS(Данные!$B$2:$B$722,9,Данные!$C$2:$C$722,1,Данные!$A$2:$A$722,">="&77234120000,Данные!$A$2:$A$722,"<="&77234120999) -> 0 | AH9: =COUNTIFS(Данные!$B$2:$B$722,9,Данные!$C$2:$C$722,1,Данные!$A$2:$A$722,">="&77234127000,Данные!$A$2:$A$722,"<="&77234127999) -> 0 | AI9: =COUNTIFS(Данные!$B$2:$B$722,9,Данные!$C$2:$C$722,1,Данные!$A$2:$A$722,">="&77234220000,Данные!$A$2:$A$722,"<="&77234220999) -> 0 | AJ9: =COUNTIFS(Данные!$B$2:$B$722,9,Данные!$C$2:$C$722,1,Данные!$A$2:$A$722,">="&77234250000,Данные!$A$2:$A$722,"<="&77234250999) -> 0 | AK9: =COUNTIFS(Данные!$B$2:$B$722,9,Данные!$C$2:$C$722,1,Данные!$A$2:$A$722,">="&77233922950,Данные!$A$2:$A$722,"<="&77233924999) -> 0 | AL9: =COUNTIFS(Данные!$B$2:$B$722,9,Данные!$C$2:$C$722,1,Данные!$A$2:$A$722,">="&77234320000,Данные!$A$2:$A$722,"<="&77234320999) -> 0 | AM9: =COUNTIFS(Данные!$B$2:$B$722,9,Данные!$C$2:$C$722,1,Данные!$A$2:$A$722,">="&77234350000,Данные!$A$2:$A$722,"<="&77234350999) -> 0 | AN9: =COUNTIFS(Данные!$B$2:$B$722,9,Данные!$C$2:$C$722,1,Данные!$A$2:$A$722,">="&77234020000,Данные!$A$2:$A$722,"<="&77234020999) -> 0 | AO9: =COUNTIFS(Данные!$B$2:$B$722,9,Данные!$C$2:$C$722,1,Данные!$A$2:$A$722,">="&77234029000,Данные!$A$2:$A$722,"<="&77234029999) -> 0 | AP9: =COUNTIFS(Данные!$B$2:$B$722,9,Данные!$C$2:$C$722,1,Данные!$A$2:$A$722,">="&77234050000,Данные!$A$2:$A$722,"<="&77234050999) -> 0 | AQ9: =COUNTIFS(Данные!$B$2:$B$722,9,Данные!$C$2:$C$722,1,Данные!$A$2:$A$722,">="&77234427000,Данные!$A$2:$A$722,"<="&77234428999) -> 0 | AR9: =COUNTIFS(Данные!$B$2:$B$722,9,Данные!$C$2:$C$722,1,Данные!$A$2:$A$722,">="&77234450000,Данные!$A$2:$A$722,"<="&77234450999) -> 0 | AS9: =COUNTIFS(Данные!$B$2:$B$722,9,Данные!$C$2:$C$722,1,Данные!$A$2:$A$722,">="&77234620000,Данные!$A$2:$A$722,"<="&77234620999) -> 0 | AT9: =COUNTIFS(Данные!$B$2:$B$722,9,Данные!$C$2:$C$722,1,Данные!$A$2:$A$722,">="&77234650000,Данные!$A$2:$A$722,"<="&77234650999) -> 0 | AU9: =COUNTIFS(Данные!$B$2:$B$722,9,Данные!$C$2:$C$722,1,Данные!$A$2:$A$722,">="&77234820000,Данные!$A$2:$A$722,"<="&77234820999) -> 0 | AV9: =COUNTIFS(Данные!$B$2:$B$722,9,Данные!$C$2:$C$722,1,Данные!$A$2:$A$722,">="&77234850000,Данные!$A$2:$A$722,"<="&77234850999) -> 0 | AW9: =COUNTIFS(Данные!$B$2:$B$722,9,Данные!$C$2:$C$722,1,Данные!$A$2:$A$722,">="&77233327000,Данные!$A$2:$A$722,"<="&77233327999) -> 0 | AX9: =COUNTIFS(Данные!$B$2:$B$722,9,Данные!$C$2:$C$722,1,Данные!$A$2:$A$722,">="&77233350000,Данные!$A$2:$A$722,"<="&77233350599) -> 0 | AY9: =COUNTIFS(Данные!$B$2:$B$722,9,Данные!$C$2:$C$722,1,Данные!$A$2:$A$722,">="&77233351000,Данные!$A$2:$A$722,"<="&77233351999) -> 0 | AZ9: =COUNTIFS(Данные!$B$2:$B$722,9,Данные!$C$2:$C$722,1,Данные!$A$2:$A$722,">="&7722440000,Данные!$A$2:$A$722,"<="&7722440999) -> 0 | BA9: =COUNTIFS(Данные!$B$2:$B$722,9,Данные!$C$2:$C$722,1,Данные!$A$2:$A$722,">="&7722442000,Данные!$A$2:$A$722,"<="&7722445659) -> 0 | BB9: =COUNTIFS(Данные!$B$2:$B$722,9,Данные!$C$2:$C$722,1,Данные!$A$2:$A$722,">="&7722450000,Данные!$A$2:$A$722,"<="&7722450199) -> 0 | BC9: =COUNTIFS(Данные!$B$2:$B$722,9,Данные!$C$2:$C$722,1,Данные!$A$2:$A$722,">="&7722451000,Данные!$A$2:$A$722,"<="&7722451374) -> 0 | BD9: =COUNTIFS(Данные!$B$2:$B$722,9,Данные!$C$2:$C$722,1,Данные!$A$2:$A$722,">="&7722452000,Данные!$A$2:$A$722,"<="&7722452299) -> 0 | BE9: =COUNTIFS(Данные!$B$2:$B$722,9,Данные!$C$2:$C$722,1,Данные!$A$2:$A$722,">="&7722453000,Данные!$A$2:$A$722,"<="&7722453816) -> 0 | BF9: =COUNTIFS(Данные!$B$2:$B$722,9,Данные!$C$2:$C$722,1,Данные!$A$2:$A$722,">="&7722454000,Данные!$A$2:$A$722,"<="&7722454099) -> 0 | BG9: =COUNTIFS(Данные!$B$2:$B$722,9,Данные!$C$2:$C$722,1,Данные!$A$2:$A$722,">="&7722458000,Данные!$A$2:$A$722,"<="&7722458999) -> 0 | BH9: =COUNTIFS(Данные!$B$2:$B$722,9,Данные!$C$2:$C$722,1,Данные!$A$2:$A$722,">="&7722630000,Данные!$A$2:$A$722,"<="&7722638549) -> 0 | BI9: =COUNTIFS(Данные!$B$2:$B$722,9,Данные!$C$2:$C$722,1,Данные!$A$2:$A$722,">="&7722639400,Данные!$A$2:$A$722,"<="&7722639899) -> 0 | BJ9: =COUNTIFS(Данные!$B$2:$B$722,9,Данные!$C$2:$C$722,1,Данные!$A$2:$A$722,">="&7725750000,Данные!$A$2:$A$722,"<="&7725750399) -> 0 | BK9: =COUNTIFS(Данные!$B$2:$B$722,9,Данные!$C$2:$C$722,1,Данные!$A$2:$A$722,">="&7723620000,Данные!$A$2:$A$722,"<="&7723621299) -> 0 | BL9: =COUNTIFS(Данные!$B$2:$B$722,9,Данные!$C$2:$C$722,1,Данные!$A$2:$A$722,">="&7723621600,Данные!$A$2:$A$722,"<="&7723623399) -> 0 | BM9: =COUNTIFS(Данные!$B$2:$B$722,9,Данные!$C$2:$C$722,1,Данные!$A$2:$A$722,">="&7725127000,Данные!$A$2:$A$722,"<="&7725127999) -> 0 | BN9: =COUNTIFS(Данные!$B$2:$B$722,9,Данные!$C$2:$C$722,1,Данные!$A$2:$A$722,">="&7723772000,Данные!$A$2:$A$722,"<="&7723724999) -> 0 | BO9: =COUNTIFS(Данные!$B$2:$B$722,9,Данные!$C$2:$C$722,1,Данные!$A$2:$A$722,">="&7723765000,Данные!$A$2:$A$722,"<="&7723765499) -> 0 | BP9: =COUNTIFS(Данные!$B$2:$B$722,9,Данные!$C$2:$C$722,1,Данные!$A$2:$A$722,">="&7723948000,Данные!$A$2:$A$722,"<="&7723948999) -> 0 | BQ9: =COUNTIFS(Данные!$B$2:$B$722,9,Данные!$C$2:$C$722,1,Данные!$A$2:$A$722,">="&7723950000,Данные!$A$2:$A$722,"<="&7723951099) -> 0 | BR9: =COUNTIFS(Данные!$B$2:$B$722,9,Данные!$C$2:$C$722,1,Данные!$A$2:$A$722,">="&7723020000,Данные!$A$2:$A$722,"<="&7723020999) -> 0 | BS9: =COUNTIFS(Данные!$B$2:$B$722,9,Данные!$C$2:$C$722,1,Данные!$A$2:$A$722,">="&7723029000,Данные!$A$2:$A$722,"<="&7723029999) -> 0 | BT9: =COUNTIFS(Данные!$B$2:$B$722,9,Данные!$C$2:$C$722,1,Данные!$A$2:$A$722,">="&7723055000,Данные!$A$2:$A$722,"<="&7723056549) -> 0 | BU9: =COUNTIFS(Данные!$B$2:$B$722,9,Данные!$C$2:$C$722,1,Данные!$A$2:$A$722,">="&7725250000,Данные!$A$2:$A$722,"<="&7725250499) -> 0 | BV9: =COUNTIFS(Данные!$B$2:$B$722,9,Данные!$C$2:$C$722,1,Данные!$A$2:$A$722,">="&7183841400,Данные!$A$2:$A$722,"<="&7183841499) -> 0 | BW9: 300 | BX9: =F9-BW9 -> -236
